<?xml version="1.0" encoding="utf-8"?>
<!-- This URDF was automatically created by SolidWorks to URDF Exporter! Originally created by Stephen Brawner (brawner@gmail.com) 
     Commit Version: 1.6.0-4-g7f85cfe  Build Version: 1.6.7995.38578
     For more information, please see http://wiki.ros.org/sw_urdf_exporter -->
<robot
  name="sff01">
  <link
    name="base_link">
    <inertial>
      <origin
        xyz="-5.6541E-17 0.11105 -4.5234E-21"
        rpy="0 0 0" />
      <mass
        value="46.814" />
      <inertia
        ixx="0.52248"
        ixy="7.6927E-18"
        ixz="5.3521E-17"
        iyy="2.3819"
        iyz="-3.7853E-19"
        izz="2.2437" />
    </inertial>
    <visual>
      <origin
        xyz="0 0 0"
        rpy="0 0 0" />
      <geometry>
        <mesh
          filename="package://sff01/meshes/base_link.STL" />
      </geometry>
      <material
        name="">
        <color
          rgba="0.79216 0.81961 0.93333 1" />
      </material>
    </visual>
    <collision>
      <origin
        xyz="0 0 0"
        rpy="0 0 0" />
      <geometry>
        <mesh
          filename="package://sff01/meshes/base_link.STL" />
      </geometry>
    </collision>
  </link>
  <link
    name="Link_1">
    <inertial>
      <origin
        xyz="-5.5868E-19 0 0.04"
        rpy="0 0 0" />
      <mass
        value="1.8241" />
      <inertia
        ixx="0.0042719"
        ixy="1.0036E-35"
        ixz="-7.228E-20"
        iyy="0.0042719"
        iyz="-3.8204E-35"
        izz="0.0066228" />
    </inertial>
    <visual>
      <origin
        xyz="0 0 0"
        rpy="0 0 0" />
      <geometry>
        <mesh
          filename="package://sff01/meshes/Link_1.STL" />
      </geometry>
      <material
        name="">
        <color
          rgba="0.29804 0.29804 0.29804 1" />
      </material>
    </visual>
    <collision>
      <origin
        xyz="0 0 0"
        rpy="0 0 0" />
      <geometry>
        <mesh
          filename="package://sff01/meshes/Link_1.STL" />
      </geometry>
    </collision>
  </link>
  <joint
    name="joint0"
    type="continuous">
    <origin
      xyz="0 -0.15 0.01"
      rpy="1.5708 0 0" />
    <parent
      link="base_link" />
    <child
      link="Link_1" />
    <axis
      xyz="0 0 1" />
  </joint>
  <link
    name="Link_2">
    <inertial>
      <origin
        xyz="-1.5687E-18 -3.4694E-18 0.04"
        rpy="0 0 0" />
      <mass
        value="1.8241" />
      <inertia
        ixx="0.0042719"
        ixy="-9.6296E-35"
        ixz="-7.2245E-20"
        iyy="0.0042719"
        iyz="-4.0377E-35"
        izz="0.0066228" />
    </inertial>
    <visual>
      <origin
        xyz="0 0 0"
        rpy="0 0 0" />
      <geometry>
        <mesh
          filename="package://sff01/meshes/Link_2.STL" />
      </geometry>
      <material
        name="">
        <color
          rgba="0.29804 0.29804 0.29804 1" />
      </material>
    </visual>
    <collision>
      <origin
        xyz="0 0 0"
        rpy="0 0 0" />
      <geometry>
        <mesh
          filename="package://sff01/meshes/Link_2.STL" />
      </geometry>
    </collision>
  </link>
  <joint
    name="joint_1"
    type="continuous">
    <origin
      xyz="0 0.15 0.01"
      rpy="1.5708 0 3.1416" />
    <parent
      link="base_link" />
    <child
      link="Link_2" />
    <axis
      xyz="0 0 1" />
  </joint>
  <link
    name="Link_3">
    <inertial>
      <origin
        xyz="5.5511E-17 6.9926E-23 0.034578"
        rpy="0 0 0" />
      <mass
        value="0.67469" />
      <inertia
        ixx="0.00033853"
        ixy="9.1306E-36"
        ixz="-2.2887E-21"
        iyy="0.00033853"
        iyz="-4.2229E-25"
        izz="0.00012971" />
    </inertial>
    <visual>
      <origin
        xyz="0 0 0"
        rpy="0 0 0" />
      <geometry>
        <mesh
          filename="package://sff01/meshes/Link_3.STL" />
      </geometry>
      <material
        name="">
        <color
          rgba="0.52941 0.54902 0.54902 1" />
      </material>
    </visual>
    <collision>
      <origin
        xyz="0 0 0"
        rpy="0 0 0" />
      <geometry>
        <mesh
          filename="package://sff01/meshes/Link_3.STL" />
      </geometry>
    </collision>
  </link>
  <joint
    name="joint_2"
    type="fixed">
    <origin
      xyz="-0.3625 0 0"
      rpy="-3.1416 0 0" />
    <parent
      link="base_link" />
    <child
      link="Link_3" />
    <axis
      xyz="0 0 0" />
  </joint>
  <link
    name="Link_4">
    <inertial>
      <origin
        xyz="-5.5511E-17 6.9926E-23 0.034578"
        rpy="0 0 0" />
      <mass
        value="0.67469" />
      <inertia
        ixx="0.00033853"
        ixy="9.1306E-36"
        ixz="-2.2887E-21"
        iyy="0.00033853"
        iyz="-4.2229E-25"
        izz="0.00012971" />
    </inertial>
    <visual>
      <origin
        xyz="0 0 0"
        rpy="0 0 0" />
      <geometry>
        <mesh
          filename="package://sff01/meshes/Link_4.STL" />
      </geometry>
      <material
        name="">
        <color
          rgba="0.52941 0.54902 0.54902 1" />
      </material>
    </visual>
    <collision>
      <origin
        xyz="0 0 0"
        rpy="0 0 0" />
      <geometry>
        <mesh
          filename="package://sff01/meshes/Link_4.STL" />
      </geometry>
    </collision>
  </link>
  <joint
    name="joint_3"
    type="fixed">
    <origin
      xyz="0.3625 0 0"
      rpy="-3.1416 0 0" />
    <parent
      link="base_link" />
    <child
      link="Link_4" />
    <axis
      xyz="0 0 0" />
  </joint>
</robot>